<robot name="anno" version="1.0">
<!-- Defining the colors used in this robot -->
  <material name="Black">
    <color rgba="0 0 0 1"/>
  </material>
  <material name="White">
    <color rgba="1 1 1 1"/>
  </material>
  <material name="Blue">
    <color rgba="0 0 1 1"/>
  </material>
  <material name="Red">
    <color rgba="1 0 0 1"/>
  </material>
  <joint name="joint1" type="revolute">
    <limit lower="-3.14000" upper="3.14000" effort="3.00000" velocity="10.00000"/>
    <origin rpy="0.00000 0.00000 0.00000" xyz="0.00000 0.00000 0.00000"/>
    <parent link="base_link"/>
    <child link="link1"/>
    <axis xyz="0.00000 0.00000 1.00000"/>
  </joint>
  <joint name="joint2" type="revolute">
    <limit lower="-2.09000" upper="2.09000" effort="3.00000" velocity="10.00000"/>
    <origin rpy="0.00000 0.00000 0.00000" xyz="0.00000 0.00000 0.23050"/>
    <parent link="link1"/>
    <child link="link2"/>
    <axis xyz="0.00000 1.00000 0.00000"/>
  </joint>
  <joint name="joint3" type="revolute">
    <limit lower="-2.50000" upper="2.50000" effort="3.00000" velocity="0.00000"/>
    <origin rpy="3.14159 1.55981 3.14159" xyz="0.00247 0.00000 0.22499"/>
    <parent link="link2"/>
    <child link="link3"/>
    <axis xyz="0.00000 1.00000 0.00000"/>
  </joint>
  <joint name="joint4" type="revolute">
    <limit lower="-3.14000" upper="3.14000" effort="3.00000" velocity="10.00000"/>
    <origin rpy="0.00000 -0.04088 0.00000" xyz="-0.00086 0.00200 0.02098"/>
    <parent link="link3"/>
    <child link="link4"/>
    <axis xyz="0.00000 0.00000 1.00000"/>
  </joint>
  <joint name="joint5" type="revolute">
    <limit lower="-2.09000" upper="2.09000" effort="3.00000" velocity="10.00000"/>
    <origin rpy="-0.00000 1.57080 0.00000" xyz="-0.00000 0.00000 0.20586"/>
    <parent link="link4"/>
    <child link="link5"/>
    <axis xyz="0.00000 1.00000 0.00000"/>
  </joint>
  <joint name="joint6" type="revolute">
    <limit lower="-3.14000" upper="3.14000" effort="3.00000" velocity="10.00000"/>
    <origin rpy="0.00000 0.02493 0.00000" xyz="0.00105 0.00000 0.04199"/>
    <parent link="link5"/>
    <child link="link6"/>
    <axis xyz="0.00000 0.00000 1.00000"/>
  </joint>
  <link name="link1">
    <collision name="link_1_collision">
      <origin rpy="1.57080 0.00000 0.00000" xyz="0.00000 0.00000 0.06900"/>
      <geometry>
        <box size="0.11984 0.15750 0.13090"/>
      </geometry>
    </collision>
    <inertial>
      <inertia ixx="0.01806" ixy="-0.00001" ixz="0.00001" iyy="0.01598" iyz="0.00004" izz="0.00671"/>
      <origin rpy="0.00000 0.00000 0.00000" xyz="0.00014 0.00466 0.11011"/>
      <mass value="2.10000"/>
    </inertial>
    <visual name="link_1">
      <origin rpy="1.57080 0.00000 0.00000" xyz="0.00000 0.00000 0.00000"/>
      <geometry>
        <mesh filename="package://anno_description/meshes/stl/link_1.stl" scale="1.00000 1.00000 1.00000"/>
      </geometry>
      <material name="White"/>
    </visual>
  </link>
  <link name="link2">
    <collision name="link_2_collision">
      <origin rpy="1.57080 -0.00062 0.00000" xyz="-0.00003 0.00000 0.04600"/>
      <geometry>
        <box size="0.08148 0.17040 0.10248"/>
      </geometry>
    </collision>
    <inertial>
      <inertia ixx="0.01517" ixy="-0.00001" ixz="-0.00002" iyy="0.01396" iyz="-0.00059" izz="0.00318"/>
      <origin rpy="0.00000 0.00000 0.00000" xyz="-0.00037 -0.00263 0.08766"/>
      <mass value="1.70000"/>
    </inertial>
    <visual name="link_2">
      <origin rpy="1.57080 0.01098 0.00000" xyz="0.00000 0.00000 0.00000"/>
      <geometry>
        <mesh filename="package://anno_description/meshes/stl/link_2.stl" scale="1.00000 1.00000 1.00000"/>
      </geometry>
      <material name="Blue"/>
    </visual>
  </link>
  <link name="link3">
    <collision name="link_3_collision">
      <origin rpy="0.00000 -0.04088 0.00000" xyz="0.00104 0.00860 -0.00091"/>
      <geometry>
        <box size="0.09480 0.17820 0.05166"/>
      </geometry>
    </collision>
    <inertial>
      <inertia ixx="0.00095" ixy="0.00006" ixz="-0.00004" iyy="0.00189" iyz="0.00003" izz="0.00174"/>
      <origin rpy="0.00000 0.00000 0.00000" xyz="-0.00468 -0.00082 0.00077"/>
      <mass value="1.00000"/>
    </inertial>
    <visual name="link_3">
      <origin rpy="-1.57080 -1.52992 3.14159" xyz="-0.00000 0.00000 0.00000"/>
      <geometry>
        <mesh filename="package://anno_description/meshes/stl/link_3.stl" scale="1.00000 1.00000 1.00000"/>
      </geometry>
      <material name="White"/>
    </visual>
  </link>
  <link name="link4">
    <collision name="link_4_collision">
      <origin rpy="1.57080 -1.54090 0.00000" xyz="0.00329 0.00000 0.08948"/>
      <geometry>
        <box size="0.14100 0.04557 0.07959"/>
      </geometry>
    </collision>
    <inertial>
      <inertia ixx="0.00118" ixy="-0.00024" ixz="0.00003" iyy="0.00497" iyz="0.00001" izz="0.00557"/>
      <origin rpy="0.00000 0.00000 0.00000" xyz="0.00018 0.00481 0.12735"/>
      <mass value="1.50000"/>
    </inertial>
    <visual name="link_4">
      <origin rpy="1.57080 -1.57080 0.00000" xyz="0.00000 0.00000 0.00000"/>
      <geometry>
        <mesh filename="package://anno_description/meshes/stl/link_4.stl" scale="1.00000 1.00000 1.00000"/>
      </geometry>
      <material name="Blue"/>
    </visual>
  </link>
  <link name="link5">
    <collision name="link_5_collision">
      <origin rpy="-1.57080 -0.10810 3.14159" xyz="0.00018 0.00150 0.00725"/>
      <geometry>
        <box size="0.05236 0.06265 0.13910"/>
      </geometry>
    </collision>
    <inertial>
      <inertia ixx="0.00054" ixy="-0.00000" ixz="-0.00000" iyy="0.00030" iyz="0.00000" izz="0.00049"/>
      <origin rpy="0.00000 0.00000 0.00000" xyz="-0.00031 0.00146 0.00293"/>
      <mass value="0.50000"/>
    </inertial>
    <visual name="link_5">
      <origin rpy="-1.57080 -0.02493 3.14159" xyz="0.00000 0.00000 0.00000"/>
      <geometry>
        <mesh filename="package://anno_description/meshes/stl/link_5.stl" scale="1.00000 1.00000 1.00000"/>
      </geometry>
      <material name="White"/>
    </visual>
  </link>
  <link name="link6">
    <collision name="link_6_collision">
      <origin rpy="-1.57080 0.00000 3.14159" xyz="0.00000 0.00005 0.00650"/>
      <geometry>
        <box size="0.05700 0.00650 0.05685"/>
      </geometry>
    </collision>
    <inertial>
      <inertia ixx="0.00001" ixy="-0.00000" ixz="-0.00000" iyy="0.00001" iyz="-0.00000" izz="0.00002"/>
      <origin rpy="0.00000 0.00000 0.00000" xyz="-0.00001 0.00001 0.00819"/>
      <mass value="0.10000"/>
    </inertial>
    <visual name="link_6">
      <origin rpy="-1.57080 0.00000 -3.14159" xyz="0.00000 0.00000 -0.00000"/>
      <geometry>
        <mesh filename="package://anno_description/meshes/stl/link_6.stl" scale="1.00000 1.00000 1.00000"/>
      </geometry>
      <material name="Blue"/>
    </visual>
  </link>
  <link name="base_link">
    <collision name="base_link_collision">
      <origin rpy="0.00000 0.00000 0.00000" xyz="0.01727 0.00000 -0.04500"/>
      <geometry>
        <box size="0.21000 0.21000 0.01289"/>
      </geometry>
    </collision>
    <!-- <inertial>
      <inertia ixx="0.25462" ixy="-0.00238" ixz="0.04021" iyy="0.36981" iyz="0.00189" izz="0.55944"/>
      <origin rpy="0.00000 0.00000 0.00000" xyz="-0.03770 -0.00031 -0.02402"/>
      <mass value="60.00000"/>
    </inertial> -->
    <visual name="base_link">
      <origin rpy="0.00000 0.00000 0.00000" xyz="0.01727 0.00000 0.00000"/>
      <geometry>
        <mesh filename="package://anno_description/meshes/stl/base_link.stl" scale="1.00000 1.00000 1.00000"/>
      </geometry>
      <material name="White"/>
    </visual>
  </link>
  <transmission name="trans_joint1">
        <type>transmission_interface/SimpleTransmission</type>
        <joint name="joint1">
            <hardwareInterface>hardware_interface/EffortJointInterface</hardwareInterface>
        </joint>
        <actuator name="joint1_motor">
            <hardwareInterface>hardware_interface/EffortJointInterface</hardwareInterface>
            <mechanicalReduction>1</mechanicalReduction>
        </actuator>
    </transmission>
    <transmission name="trans_joint2">
        <type>transmission_interface/SimpleTransmission</type>
        <joint name="joint2">
            <hardwareInterface>hardware_interface/EffortJointInterface</hardwareInterface>
        </joint>
        <actuator name="joint2_motor">
            <hardwareInterface>hardware_interface/EffortJointInterface</hardwareInterface>
            <mechanicalReduction>1</mechanicalReduction>
        </actuator>
    </transmission>
    <transmission name="trans_joint3">
        <type>transmission_interface/SimpleTransmission</type>
        <joint name="joint3">
            <hardwareInterface>hardware_interface/EffortJointInterface</hardwareInterface>
        </joint>
        <actuator name="joint3_motor">
            <hardwareInterface>hardware_interface/EffortJointInterface</hardwareInterface>
            <mechanicalReduction>1</mechanicalReduction>
        </actuator>
    </transmission>
    <transmission name="trans_joint4">
        <type>transmission_interface/SimpleTransmission</type>
        <joint name="joint4">
            <hardwareInterface>hardware_interface/EffortJointInterface</hardwareInterface>
        </joint>
        <actuator name="joint4_motor">
            <hardwareInterface>hardware_interface/EffortJointInterface</hardwareInterface>
            <mechanicalReduction>1</mechanicalReduction>
        </actuator>
    </transmission>
    <transmission name="trans_joint5">
        <type>transmission_interface/SimpleTransmission</type>
        <joint name="joint5">
            <hardwareInterface>hardware_interface/EffortJointInterface</hardwareInterface>
        </joint>
        <actuator name="joint5_motor">
            <hardwareInterface>hardware_interface/EffortJointInterface</hardwareInterface>
            <mechanicalReduction>1</mechanicalReduction>
        </actuator>
    </transmission>
    <transmission name="trans_joint6">
        <type>transmission_interface/SimpleTransmission</type>
        <joint name="joint6">
            <hardwareInterface>hardware_interface/EffortJointInterface</hardwareInterface>
        </joint>
        <actuator name="joint6_motor">
            <hardwareInterface>hardware_interface/EffortJointInterface</hardwareInterface>
            <mechanicalReduction>1</mechanicalReduction>
        </actuator>
    </transmission>
    <gazebo>
        <plugin name="gazebo_ros_control" filename="libgazebo_ros_control.so">
            <robotNamespace>/</robotNamespace>
        </plugin>
    </gazebo>
</robot>